<?xml version="1.0" encoding="UTF-8"?>
<robot name="knight">

    <link name="dummy_link" />

    <joint name="base_joint" type="fixed">
        <parent link="dummy_link" />
        <child link="base_link" />
        <origin xyz="0 0 0" rpy="0 0 0" />
    </joint>

    <link name="base_link">
        <visual>
            <origin xyz="0 0 0" rpy="0 0 0" />
            <geometry>
                <mesh filename="package://knight_description/meshes/body.stl" scale="0.001 0.001 0.001" />
            </geometry>
        </visual>

        <collision>
            <origin xyz="0 0 0" rpy="0 0 0" />
            <geometry>
                <mesh filename="package://knight_description/meshes/body.stl" scale="0.001 0.001 0.001" />
            </geometry>
        </collision>

        <inertial>
            <origin xyz="0 0 0" rpy="0 0 0" />
            <mass value="4" />
            <inertia ixx="0.01" ixy="0" ixz="0" iyy="0.01" iyz="0" izz="0.02" />
        </inertial>
    </link>

    <joint name="right_wheel_joint" type="continuous">
        <axis rpy="0 0 0" xyz="-1 0 0" />
        <parent link="base_link" />
        <child link="right_wheel_link" />
        <origin xyz="0.0815 -0.0875 0.0378" rpy="0 0 0" />
    </joint>

    <link name="right_wheel_link">
        <visual>
            <origin xyz="0 0 0" rpy="0 0 0" />
            <geometry>
                <mesh filename="package://knight_description/meshes/wheel.stl" scale="0.001 0.001 0.001" />
            </geometry>
        </visual>

        <collision>
            <origin xyz="0 0 0" rpy="0 0 0" />
            <geometry>
                <mesh filename="package://knight_description/meshes/wheel.stl" scale="0.001 0.001 0.001" />
            </geometry>
        </collision>

        <inertial>
            <origin xyz="0 0 0" rpy="0 0 0" />
            <mass value="0.5" />
            <inertia ixx="0.001" ixy="0" ixz="0" iyy="0.002" iyz="0" izz="0.001" />
        </inertial>
    </link>

    <joint name="left_wheel_joint" type="continuous">
        <axis rpy="0 0 0" xyz="-1 0 0" />
        <parent link="base_link" />
        <child link="left_wheel_link" />
        <origin xyz="-0.0815 -0.0875 0.0378" rpy="0 0 0" />
    </joint>

    <link name="left_wheel_link">
        <visual>
            <origin xyz="0 0 0" rpy="0 0 0" />
            <geometry>
                <mesh filename="package://knight_description/meshes/wheel.stl" scale="0.001 0.001 0.001" />
            </geometry>
        </visual>

        <collision>
            <origin xyz="0 0 0" rpy="0 0 0" />
            <geometry>
                <mesh filename="package://knight_description/meshes/wheel.stl" scale="0.001 0.001 0.001" />
            </geometry>
        </collision>

        <inertial>
            <origin xyz="0 0 0" rpy="0 0 0" />
            <mass value="0.5" />
            <inertia ixx="0.001" ixy="0" ixz="0" iyy="0.002" iyz="0" izz="0.001" />
        </inertial>
    </link>

    <joint name="imu_joint" type="fixed">
        <parent link="base_link" />
        <child link="imu_link" />
        <origin xyz="0 0.140 0.026" rpy="0 0 0" />
    </joint>

    <link name="imu_link">
        <visual>
            <origin xyz="0 0 0" rpy="0 0 0" />
            <geometry>
                <box size="0.015 0.015 0.015" />
            </geometry>
        </visual>
    </link>

    <joint name="lidar_joint" type="fixed">
        <parent link="base_link" />
        <child link="lidar_link" />
        <origin xyz="0 0 0.19" rpy="0 0 0" />
    </joint>

    <link name="lidar_link">
        <visual>
            <origin xyz="0 0 0" rpy="0 0 0" />
            <geometry>
                <box size="0.015 0.015 0.015" />
            </geometry>
        </visual>
    </link>

    <gazebo>
        <plugin filename="libgazebo_ros_diff_drive.so" name="differential_drive_controller">
            <alwaysOn>true</alwaysOn>
            <updateRate>20</updateRate>
            <leftJoint>left_wheel_joint</leftJoint>
            <rightJoint>right_wheel_joint</rightJoint>
            <wheelSeparation>0.163</wheelSeparation>
            <wheelDiameter>0.0756</wheelDiameter>
            <torque>0.5</torque>
            <commandTopic>knight/cmd_vel</commandTopic>
            <odometryTopic>knight/odom</odometryTopic>
            <odometryFrame>odom</odometryFrame>
            <robotBaseFrame>base_link</robotBaseFrame>
        </plugin>
        <plugin filename="libgazebo_ros_imu.so" name="knight_imu">
            <alwaysOn>true</alwaysOn>
            <updateRate>30</updateRate>
            <visualize>true</visualize>
            <bodyName>imu_link</bodyName>
            <topicName>knight/imu</topicName>
        </plugin>
    </gazebo>

    <gazebo reference="lidar_link">
        <sensor type="ray" name="knight_lidar_sensor">
            <pose>0 0 0  0 0 0</pose>
            <visualize>true</visualize>
            <update_rate>30</update_rate>
            <ray>
                <scan>
                    <horizontal>
                        <samples>100</samples>
                        <resolution>1</resolution>
                        <min_angle>0</min_angle>
                        <max_angle>3.141592</max_angle>
                    </horizontal>
                </scan>
                <range>
                    <min>0.20</min>
                    <max>3.0</max>
                    <resolution>0.01</resolution>
                </range>
                <noise>
                    <type>gaussian</type>
                    <mean>0.0</mean>
                    <stddev>0.01</stddev>
                </noise>
            </ray>
            <plugin filename="libgazebo_ros_laser.so" name="knight_lidar">
                <topicName>/knight/lidar</topicName>
                <frameName>lidar_link</frameName>
            </plugin>
        </sensor>
    </gazebo>

</robot>
